2017-12-22 15:39:46,084 ERROR: Exception on /index [GET] [in /Users/mfabian1/Desktop/microblog/venv/lib/python3.6/site-packages/flask/app.py:1560]
Traceback (most recent call last):
  File "/Users/mfabian1/Desktop/microblog/venv/lib/python3.6/site-packages/flask/app.py", line 1982, in wsgi_app
    response = self.full_dispatch_request()
  File "/Users/mfabian1/Desktop/microblog/venv/lib/python3.6/site-packages/flask/app.py", line 1614, in full_dispatch_request
    rv = self.handle_user_exception(e)
  File "/Users/mfabian1/Desktop/microblog/venv/lib/python3.6/site-packages/flask/app.py", line 1517, in handle_user_exception
    reraise(exc_type, exc_value, tb)
  File "/Users/mfabian1/Desktop/microblog/venv/lib/python3.6/site-packages/flask/_compat.py", line 33, in reraise
    raise value
  File "/Users/mfabian1/Desktop/microblog/venv/lib/python3.6/site-packages/flask/app.py", line 1612, in full_dispatch_request
    rv = self.dispatch_request()
  File "/Users/mfabian1/Desktop/microblog/venv/lib/python3.6/site-packages/flask/app.py", line 1598, in dispatch_request
    return self.view_functions[rule.endpoint](**req.view_args)
  File "/Users/mfabian1/Desktop/microblog/venv/lib/python3.6/site-packages/flask_login/utils.py", line 261, in decorated_view
    return func(*args, **kwargs)
  File "/Users/mfabian1/Desktop/microblog/app/routes.py", line 27, in index
    return render_template('index.html', title='Home', form=form, posts=posts)
  File "/Users/mfabian1/Desktop/microblog/venv/lib/python3.6/site-packages/flask/templating.py", line 134, in render_template
    context, ctx.app)
  File "/Users/mfabian1/Desktop/microblog/venv/lib/python3.6/site-packages/flask/templating.py", line 116, in _render
    rv = template.render(context)
  File "/Users/mfabian1/Desktop/microblog/venv/lib/python3.6/site-packages/jinja2/asyncsupport.py", line 76, in render
    return original_render(self, *args, **kwargs)
  File "/Users/mfabian1/Desktop/microblog/venv/lib/python3.6/site-packages/jinja2/environment.py", line 1008, in render
    return self.environment.handle_exception(exc_info, True)
  File "/Users/mfabian1/Desktop/microblog/venv/lib/python3.6/site-packages/jinja2/environment.py", line 780, in handle_exception
    reraise(exc_type, exc_value, tb)
  File "/Users/mfabian1/Desktop/microblog/venv/lib/python3.6/site-packages/jinja2/_compat.py", line 37, in reraise
    raise value.with_traceback(tb)
  File "/Users/mfabian1/Desktop/microblog/app/templates/index.html", line 1, in top-level template code
    {% extends "base.html" %}
  File "/Users/mfabian1/Desktop/microblog/app/templates/base.html", line 32, in top-level template code
    {% block content %}{% endblock %}
  File "/Users/mfabian1/Desktop/microblog/app/templates/index.html", line 19, in block "content"
    {% include '_post.html' %}
  File "/Users/mfabian1/Desktop/microblog/app/templates/_post.html", line 4, in top-level template code
    <td><a href="{{ url_for('user', post.author.username) }}">{{ post.author.username }}</a> says:<br>{{ post.body }}</td>
TypeError: url_for() takes 1 positional argument but 2 were given
2017-12-22 15:40:21,644 INFO: Microblog startup [in /Users/mfabian1/Desktop/microblog/app/__init__.py:40]
2017-12-22 15:56:05,612 INFO: Microblog startup [in /Users/mfabian1/Desktop/microblog/app/__init__.py:40]
2017-12-22 16:03:06,737 INFO: Microblog startup [in /Users/mfabian1/Desktop/microblog/app/__init__.py:40]
2017-12-22 16:04:06,217 INFO: Microblog startup [in /Users/mfabian1/Desktop/microblog/app/__init__.py:40]
